Workbook
Name SegmentaciónDeDatos_Años: #N/A
Name SegmentaciónDeDatos_Centro_de_costos: #N/A
Name SegmentaciónDeDatos_Nombre_Ciudad1: #N/A
Name SegmentaciónDeDatos_Nombre_Cliente: #N/A
Name SegmentaciónDeDatos_Nombre_Departamento: #N/A
Name SegmentaciónDeDatos_Nombre_Subgrupo: #N/A
Name SegmentaciónDeDatos_Nombre_vendedor: #N/A
Name SegmentaciónDeDatos_Producto: #N/A
Name SegmentaciónDeDatos_Semestre: #N/A

Sheet VENTAS
A1: vendedor | B1: Nombre vendedor | C1: num_doc | D1: fecha | E1: Semestre | F1: dia_pla | G1: item | H1: Producto | I1: cantidad | J1: pre_tot | K1: cliente | L1: Nombre Cliente | M1: cod_subgrupo | N1: Nombre Subgrupo | O1: cod_dep | P1: Nombre Departamento | Q1: cod_ciu | R1: Nombre Ciudad | S1: cod_cco | T1: Centro de costos | U1: TRM | V1: pre_tot_US
A2: 005 | B2: =VLOOKUP(A2,Códigos!$H$3:$I$19,2,0) -> JENNY GOMEZ VALENCIA | C2: FM-26269 | D2: 41649 | E2: Sem 1 | F2: 75 | G2: 1500-0005 | H2: =VLOOKUP(G2,Códigos!$K$2:$L$250,2,0) -> BRAITEX CBSX-PVO | I2: 300 | J2: 17064000 | K2: 890300684 | L2: =VLOOKUP(K2,Códigos!$N$2:$O$376,2,0) -> RECKITT Y BENCKISER COLOMBIA S.A. | M2: 001 | N2: =VLOOKUP(M2,Códigos!$Q$2:$R$26,2,0) -> BASF QUIMICA | O2: 76 | P2: =VLOOKUP(O2,Códigos!$B$2:$C$19,2,0) -> VALLE DEL CAUCA | Q2: 76001 | R2: =VLOOKUP(Q2,Códigos!$E$2:$F$52,2,0) -> CALI | S2: 001 | T2: =VLOOKUP(S2,Códigos!$T$3:$U$14,2,0) -> BIOINDUSTRIA | U2: 1884.47 | V2: 9055.0659
A3: 003 | B3: =VLOOKUP(A3,Códigos!$H$3:$I$19,2,0) -> LINA MERCEDES RUBIO GOMEZ | C3: FM-26261 | D3: 41649 | E3: Sem 1 | F3: 30 | G3: 801-0069 | H3: =VLOOKUP(G3,Códigos!$K$2:$L$250,2,0) -> PURAFECT BLEND 102E | I3: 1000 | J3: 26005690 | K3: 860000135 | L3: =VLOOKUP(K3,Códigos!$N$2:$O$376,2,0) -> AZUL K S.A. | M3: 021 | N3: =VLOOKUP(M3,Códigos!$Q$2:$R$26,2,0) -> GENENOR DETERGENTES | O3: 11 | P3: =VLOOKUP(O3,Códigos!$B$2:$C$19,2,0) -> BOGOTÁ, D.C. | Q3: 11001 | R3: =VLOOKUP(Q3,Códigos!$E$2:$F$52,2,0) -> BOGOTÁ, D.C. | S3: 001 | T3: =VLOOKUP(S3,Códigos!$T$3:$U$14,2,0) -> BIOINDUSTRIA | U3: 1884.47 | V3: 13800.002
A4: 002 | B4: =VLOOKUP(A4,Códigos!$H$3:$I$19,2,0) -> KAREN ANDREA GUALDRON | C4: FM-26262 | D4: 41649 | E4: Sem 1 | F4: 45 | G4: 600-0012 | H4: =VLOOKUP(G4,Códigos!$K$2:$L$250,2,0) -> ANTIFOAM 1520 - TAMBOR | I4: 200 | J4: 2562880 | K4: 860052601 | L4: =VLOOKUP(K4,Códigos!$N$2:$O$376,2,0) -> EXRO S.A.S. | M4: 101 | N4: =VLOOKUP(M4,Códigos!$Q$2:$R$26,2,0) -> XIAMETER | O4: 11 | P4: =VLOOKUP(O4,Códigos!$B$2:$C$19,2,0) -> BOGOTÁ, D.C. | Q4: 11001 | R4: =VLOOKUP(Q4,Códigos!$E$2:$F$52,2,0) -> BOGOTÁ, D.C. | S4: 002 | T4: =VLOOKUP(S4,Códigos!$T$3:$U$14,2,0) -> ESPECIALIDADES QUIMICAS | U4: 1884.47 | V4: 1360.0004
A5: 005 | B5: =VLOOKUP(A5,Códigos!$H$3:$I$19,2,0) -> JENNY GOMEZ VALENCIA | C5: FM-26265 | D5: 41649 | E5: Sem 1 | F5: 60 | G5: 900-0001 | H5: =VLOOKUP(G5,Códigos!$K$2:$L$250,2,0) -> LUDOX CL-P | I5: 535.24 | J5: 5648403.8 | K5: 890300406 | L5: =VLOOKUP(K5,Códigos!$N$2:$O$376,2,0) -> CARTON DE COLOMBIA S.A. | M5: 002 | N5: =VLOOKUP(M5,Códigos!$Q$2:$R$26,2,0) -> GENENCOR CUERO | O5: 76 | P5: =VLOOKUP(O5,Códigos!$B$2:$C$19,2,0) -> VALLE DEL CAUCA | Q5: 76892 | R5: =VLOOKUP(Q5,Códigos!$E$2:$F$52,2,0) -> YUMBO | S5: 002 | T5: =VLOOKUP(S5,Códigos!$T$3:$U$14,2,0) -> ESPECIALIDADES QUIMICAS | U5: 1884.47 | V5: 2997.3434
A6: 014 | B6: =VLOOKUP(A6,Códigos!$H$3:$I$19,2,0) -> SUSANA ESTRADA E. | C6: FM-26270 | D6: 41649 | E6: Sem 1 | F6: 60 | G6: 700-0001 | H6: =VLOOKUP(G6,Códigos!$K$2:$L$250,2,0) -> TIZOR IAM | I6: 200 | J6: 3218674 | K6: 890917295 | L6: =VLOOKUP(K6,Códigos!$N$2:$O$376,2,0) -> COLORQUIMICA S.A. | M6: 100 | N6: =VLOOKUP(M6,Códigos!$Q$2:$R$26,2,0) -> DORF KETAL | O6: 05 | P6: =VLOOKUP(O6,Códigos!$B$2:$C$19,2,0) -> ANTIOQUIA | Q6: 05380 | R6: =VLOOKUP(Q6,Códigos!$E$2:$F$52,2,0) -> LA ESTRELLA | S6: 002 | T6: =VLOOKUP(S6,Códigos!$T$3:$U$14,2,0) -> ESPECIALIDADES QUIMICAS | U6: 1884.47 | V6: 1707.9996
A7: 014 | B7: =VLOOKUP(A7,Códigos!$H$3:$I$19,2,0) -> SUSANA ESTRADA E. | C7: FM-26259 | D7: 41649 | E7: Sem 1 | F7: 60 | G7: 600-0045 | H7: =VLOOKUP(G7,Códigos!$K$2:$L$250,2,0) -> ADITIVO 71 | I7: 20 | J7: 1634966.2 | K7: 890917295 | L7: =VLOOKUP(K7,Códigos!$N$2:$O$376,2,0) -> COLORQUIMICA S.A. | M7: 001 | N7: =VLOOKUP(M7,Códigos!$Q$2:$R$26,2,0) -> BASF QUIMICA | O7: 05 | P7: =VLOOKUP(O7,Códigos!$B$2:$C$19,2,0) -> ANTIOQUIA | Q7: 05380 | R7: =VLOOKUP(Q7,Códigos!$E$2:$F$52,2,0) -> LA ESTRELLA | S7: 002 | T7: =VLOOKUP(S7,Códigos!$T$3:$U$14,2,0) -> ESPECIALIDADES QUIMICAS | U7: 1884.47 | V7: 867.60001
A8: 014 | B8: =VLOOKUP(A8,Códigos!$H$3:$I$19,2,0) -> SUSANA ESTRADA E. | C8: FM-26260 | D8: 41649 | E8: Sem 1 | F8: 60 | G8: 600-0049 | H8: =VLOOKUP(G8,Códigos!$K$2:$L$250,2,0) -> ADITIVO 57 * 200 KG | I8: 63 | J8: 3858452.6 | K8: 890908649 | L8: =VLOOKUP(K8,Códigos!$N$2:$O$376,2,0) -> TINTAS S.A.S. | M8: 001 | N8: =VLOOKUP(M8,Códigos!$Q$2:$R$26,2,0) -> BASF QUIMICA | O8: 05 | P8: =VLOOKUP(O8,Códigos!$B$2:$C$19,2,0) -> ANTIOQUIA | Q8: 05001 | R8: =VLOOKUP(Q8,Códigos!$E$2:$F$52,2,0) -> MEDELLÍN | S8: 002 | T8: =VLOOKUP(S8,Códigos!$T$3:$U$14,2,0) -> ESPECIALIDADES QUIMICAS | U8: 1884.47 | V8: 2047.5002
A9: 014 | B9: =VLOOKUP(A9,Códigos!$H$3:$I$19,2,0) -> SUSANA ESTRADA E. | C9: FM-26263 | D9: 41649 | E9: Sem 1 | F9: 0 | G9: 1400-0001 | H9: =VLOOKUP(G9,Códigos!$K$2:$L$250,2,0) -> SANTICIZER 160 | I9: 10 | J9: 115000 | K9: 98584936 | L9: =VLOOKUP(K9,Códigos!$N$2:$O$376,2,0) -> TOBON MONCADA WILFREDY ALONSO | M9: 003 | N9: =VLOOKUP(M9,Códigos!$Q$2:$R$26,2,0) -> FERRO | O9: 05 | P9: =VLOOKUP(O9,Códigos!$B$2:$C$19,2,0) -> ANTIOQUIA | Q9: 05001 | R9: =VLOOKUP(Q9,Códigos!$E$2:$F$52,2,0) -> MEDELLÍN | S9: 002 | T9: =VLOOKUP(S9,Códigos!$T$3:$U$14,2,0) -> ESPECIALIDADES QUIMICAS | U9: 1884.47 | V9: 61.025116
A10: 001 | B10: =VLOOKUP(A10,Códigos!$H$3:$I$19,2,0) -> TEXTILERAS BOGOTA | C10: FM-26268 | D10: 41649 | E10: Sem 1 | F10: 30 | G10: 801-0006 | H10: =VLOOKUP(G10,Códigos!$K$2:$L$250,2,0) -> CATALASE T100 | I10: 100 | J10: 950000 | K10: 860000452 | L10: =VLOOKUP(K10,Códigos!$N$2:$O$376,2,0) -> MANUFACTURAS ELIOT S.A.S. | M10: 002 | N10: =VLOOKUP(M10,Códigos!$Q$2:$R$26,2,0) -> GENENCOR CUERO | O10: 11 | P10: =VLOOKUP(O10,Códigos!$B$2:$C$19,2,0) -> BOGOTÁ, D.C. | Q10: 11001 | R10: =VLOOKUP(Q10,Códigos!$E$2:$F$52,2,0) -> BOGOTÁ, D.C. | S10: 001 | T10: =VLOOKUP(S10,Códigos!$T$3:$U$14,2,0) -> BIOINDUSTRIA | U10: 1884.47 | V10: 504.12052
A11: 005 | B11: =VLOOKUP(A11,Códigos!$H$3:$I$19,2,0) -> JENNY GOMEZ VALENCIA | C11: FM-26274 | D11: 41650 | E11: Sem 1 | F11: 90 | G11: 801-0015 | H11: =VLOOKUP(G11,Códigos!$K$2:$L$250,2,0) -> INDESIZE 350 DLC | I11: 25 | J11: 112100 | K11: 816001697 | L11: =VLOOKUP(K11,Códigos!$N$2:$O$376,2,0) -> LAVA MASTER LTDA. | M11: 002 | N11: =VLOOKUP(M11,Códigos!$Q$2:$R$26,2,0) -> GENENCOR CUERO | O11: 66 | P11: =VLOOKUP(O11,Códigos!$B$2:$C$19,2,0) -> RISARALDA | Q11: 66170 | R11: =VLOOKUP(Q11,Códigos!$E$2:$F$52,2,0) -> DOSQUEBRADAS | S11: 001 | T11: =VLOOKUP(S11,Códigos!$T$3:$U$14,2,0) -> BIOINDUSTRIA | U11: 1865.07 | V11: 60.104983
A12: 014 | B12: =VLOOKUP(A12,Códigos!$H$3:$I$19,2,0) -> SUSANA ESTRADA E. | C12: FM-26271 | D12: 41650 | E12: Sem 1 | F12: 60 | G12: 600-0010 | H12: =VLOOKUP(G12,Códigos!$K$2:$L$250,2,0) -> ANTIFOAM 1430 | I12: 400 | J12: 5028228 | K12: 890900652 | L12: =VLOOKUP(K12,Códigos!$N$2:$O$376,2,0) -> INVESA S.A. | M12: 101 | N12: =VLOOKUP(M12,Códigos!$Q$2:$R$26,2,0) -> XIAMETER | O12: 05 | P12: =VLOOKUP(O12,Códigos!$B$2:$C$19,2,0) -> ANTIOQUIA | Q12: 05266 | R12: =VLOOKUP(Q12,Códigos!$E$2:$F$52,2,0) -> ENVIGADO | S12: 002 | T12: =VLOOKUP(S12,Códigos!$T$3:$U$14,2,0) -> ESPECIALIDADES QUIMICAS | U12: 1865.07 | V12: 2695.9996
A13: 002 | B13: =VLOOKUP(A13,Códigos!$H$3:$I$19,2,0) -> KAREN ANDREA GUALDRON | C13: FM-26278 | D13: 41650 | E13: Sem 1 | F13: 30 | G13: 600-0096 | H13: =VLOOKUP(G13,Códigos!$K$2:$L$250,2,0) -> ADITIVO 56 * 200 KG | I13: 10 | J13: 969836.4 | K13: 800160933 | L13: =VLOOKUP(K13,Códigos!$N$2:$O$376,2,0) -> OLAFLEX S.A.S. | M13: 001 | N13: =VLOOKUP(M13,Códigos!$Q$2:$R$26,2,0) -> BASF QUIMICA | O13: 11 | P13: =VLOOKUP(O13,Códigos!$B$2:$C$19,2,0) -> BOGOTÁ, D.C. | Q13: 11001 | R13: =VLOOKUP(Q13,Códigos!$E$2:$F$52,2,0) -> BOGOTÁ, D.C. | S13: 002 | T13: =VLOOKUP(S13,Códigos!$T$3:$U$14,2,0) -> ESPECIALIDADES QUIMICAS | U13: 1865.07 | V13: 520
... A9755: 036 | B9755: =VLOOKUP(A9755,Códigos!$H$3:$I$19,2,0) -> KAREN SEGURA | C9755: DVV-000400A | D9755: 42735 | E9755: Sem 2 | F9755: 0 | G9755: 900-0010 | H9755: =VLOOKUP(G9755,Códigos!$K$2:$L$250,2,0) -> SYLOWHITE SM 405 | I9755: 7500 | J9755: 48750000 | K9755: 800131306 | L9755: =VLOOKUP(K9755,Códigos!$N$2:$O$376,2,0) -> BATALLON DE INFANTERIA No. 23 "VENCEDORES" | M9755: 002 | N9755: =VLOOKUP(M9755,Códigos!$Q$2:$R$26,2,0) -> GENENCOR CUERO | O9755: 76 | P9755: =VLOOKUP(O9755,Códigos!$B$2:$C$19,2,0) -> VALLE DEL CAUCA | Q9755: 76147 | R9755: =VLOOKUP(Q9755,Códigos!$E$2:$F$52,2,0) -> CARTAGO | S9755: 002 | T9755: =VLOOKUP(S9755,Códigos!$T$3:$U$14,2,0) -> ESPECIALIDADES QUIMICAS | U9755: 2392.46 | V9755: 20376.516
A9756: 007 | B9756: =VLOOKUP(A9756,Códigos!$H$3:$I$19,2,0) -> NATALY VELA | C9756: MED-37231 | D9756: 42748 | E9756: Sem 1 | F9756: 30 | G9756: 801-0062 | H9756: =VLOOKUP(G9756,Códigos!$K$2:$L$250,2,0) -> PURAFECT 4000 L/ EFFECTENZ P 100 | I9756: 25 | J9756: 1263522.8 | K9756: 860525726 | L9756: =VLOOKUP(K9756,Códigos!$N$2:$O$376,2,0) -> INDULATEX S.A. | M9756: 021 | N9756: =VLOOKUP(M9756,Códigos!$Q$2:$R$26,2,0) -> GENENOR DETERGENTES | O9756: 25 | P9756: =VLOOKUP(O9756,Códigos!$B$2:$C$19,2,0) -> CUNDINAMARCA | Q9756: 25286 | R9756: =VLOOKUP(Q9756,Códigos!$E$2:$F$52,2,0) -> FUNZA | S9756: 001 | T9756: =VLOOKUP(S2,Códigos!$T$3:$U$14,2,0) -> BIOINDUSTRIA | U9756: 2406.71 | V9756: 525
A9757: 032 | B9757: =VLOOKUP(A9757,Códigos!$H$3:$I$19,2,0) -> ALEXANDRA CASTILLO | C9757: FB-27350 | D9757: 42748 | E9757: Sem 1 | F9757: 60 | G9757: 700-0001 | H9757: =VLOOKUP(G9757,Códigos!$K$2:$L$250,2,0) -> TIZOR IAM | I9757: 1800 | J9757: 30835836 | K9757: 860006160 | L9757: =VLOOKUP(K9757,Códigos!$N$2:$O$376,2,0) -> PLASTILENE S.A. | M9757: 100 | N9757: =VLOOKUP(M9757,Códigos!$Q$2:$R$26,2,0) -> DORF KETAL | O9757: 25 | P9757: =VLOOKUP(O9757,Códigos!$B$2:$C$19,2,0) -> CUNDINAMARCA | Q9757: 11001 | R9757: =VLOOKUP(Q9757,Códigos!$E$2:$F$52,2,0) -> BOGOTÁ, D.C. | S9757: 002 | T9757: =VLOOKUP(S9757,Códigos!$T$3:$U$14,2,0) -> ESPECIALIDADES QUIMICAS | U9757: 2406.71 | V9757: 12812.444
A9758: 022 | B9758: =VLOOKUP(A9758,Códigos!$H$3:$I$19,2,0) -> MARIA ELENA PELAEZ | C9758: MED-37225 | D9758: 42748 | E9758: Sem 1 | F9758: 60 | G9758: 1000-0001 | H9758: =VLOOKUP(G9758,Códigos!$K$2:$L$250,2,0) -> INDICANT-COLOR | I9758: 400 | J9758: 1800000 | K9758: 891408135 | L9758: =VLOOKUP(K9758,Códigos!$N$2:$O$376,2,0) -> NICOLE S.A.S. | M9758: 005 | N9758: =VLOOKUP(M9758,Códigos!$Q$2:$R$26,2,0) -> ANDICOL | O9758: 66 | P9758: =VLOOKUP(O9758,Códigos!$B$2:$C$19,2,0) -> RISARALDA | Q9758: 66170 | R9758: =VLOOKUP(Q9758,Códigos!$E$2:$F$52,2,0) -> DOSQUEBRADAS | S9758: 001 | T9758: =VLOOKUP(S9758,Códigos!$T$3:$U$14,2,0) -> BIOINDUSTRIA | U9758: 2406.71 | V9758: 747.90897
A9759: 005 | B9759: =VLOOKUP(A9759,Códigos!$H$3:$I$19,2,0) -> JENNY GOMEZ VALENCIA | C9759: MED-37219 | D9759: 42748 | E9759: Sem 1 | F9759: 60 | G9759: 900-0001 | H9759: =VLOOKUP(G9759,Códigos!$K$2:$L$250,2,0) -> LUDOX CL-P | I9759: 267.62 | J9759: 3993425.6 | K9759: 890300406 | L9759: =VLOOKUP(K9759,Códigos!$N$2:$O$376,2,0) -> CARTON DE COLOMBIA S.A. | M9759: 002 | N9759: =VLOOKUP(M9759,Códigos!$Q$2:$R$26,2,0) -> GENENCOR CUERO | O9759: 76 | P9759: =VLOOKUP(O9759,Códigos!$B$2:$C$19,2,0) -> VALLE DEL CAUCA | Q9759: 76892 | R9759: =VLOOKUP(Q9759,Códigos!$E$2:$F$52,2,0) -> YUMBO | S9759: 002 | T9759: =VLOOKUP(S9759,Códigos!$T$3:$U$14,2,0) -> ESPECIALIDADES QUIMICAS | U9759: 2406.71 | V9759: 1659.2883
A9760: 007 | B9760: =VLOOKUP(A9760,Códigos!$H$3:$I$19,2,0) -> NATALY VELA | C9760: MED-37228 | D9760: 42748 | E9760: Sem 1 | F9760: 0 | G9760: 800-0068 | H9760: =VLOOKUP(G9760,Códigos!$K$2:$L$250,2,0) -> PURAPOWER/ SMARTENZ 1050 | I9760: 40 | J9760: 2888052 | K9760: 860057664 | L9760: =VLOOKUP(K9760,Códigos!$N$2:$O$376,2,0) -> MARCHEN S.A. | M9760: 021 | N9760: =VLOOKUP(M9760,Códigos!$Q$2:$R$26,2,0) -> GENENOR DETERGENTES | O9760: 11 | P9760: =VLOOKUP(O9760,Códigos!$B$2:$C$19,2,0) -> BOGOTÁ, D.C. | Q9760: 11001 | R9760: =VLOOKUP(Q9760,Códigos!$E$2:$F$52,2,0) -> BOGOTÁ, D.C. | S9760: 001 | T9760: =VLOOKUP(S9760,Códigos!$T$3:$U$14,2,0) -> BIOINDUSTRIA | U9760: 2406.71 | V9760: 1200
A9761: 003 | B9761: =VLOOKUP(A9761,Códigos!$H$3:$I$19,2,0) -> LINA MERCEDES RUBIO GOMEZ | C9761: MED-37224 | D9761: 42748 | E9761: Sem 1 | F9761: 60 | G9761: 801-0085 | H9761: =VLOOKUP(G9761,Códigos!$K$2:$L$250,2,0) -> PURASTAR ST 15000L | I9761: 400 | J9761: 20216364 | K9761: 860007955 | L9761: =VLOOKUP(K9761,Códigos!$N$2:$O$376,2,0) -> DETERGENTES LTDA | M9761: 021 | N9761: =VLOOKUP(M9761,Códigos!$Q$2:$R$26,2,0) -> GENENOR DETERGENTES | O9761: 11 | P9761: =VLOOKUP(O9761,Códigos!$B$2:$C$19,2,0) -> BOGOTÁ, D.C. | Q9761: 11001 | R9761: =VLOOKUP(Q9761,Códigos!$E$2:$F$52,2,0) -> BOGOTÁ, D.C. | S9761: 001 | T9761: =VLOOKUP(S9761,Códigos!$T$3:$U$14,2,0) -> BIOINDUSTRIA | U9761: 2406.71 | V9761: 8400
A9762: 003 | B9762: =VLOOKUP(A9762,Códigos!$H$3:$I$19,2,0) -> LINA MERCEDES RUBIO GOMEZ | C9762: MED-37229 | D9762: 42748 | E9762: Sem 1 | F9762: 30 | G9762: 801-0069 | H9762: =VLOOKUP(G9762,Códigos!$K$2:$L$250,2,0) -> PURAFECT BLEND 102E | I9762: 2000 | J9762: 68350560 | K9762: 860000135 | L9762: =VLOOKUP(K9762,Códigos!$N$2:$O$376,2,0) -> AZUL K S.A. | M9762: 021 | N9762: =VLOOKUP(M9762,Códigos!$Q$2:$R$26,2,0) -> GENENOR DETERGENTES | O9762: 11 | P9762: =VLOOKUP(O9762,Códigos!$B$2:$C$19,2,0) -> BOGOTÁ, D.C. | Q9762: 11001 | R9762: =VLOOKUP(Q9762,Códigos!$E$2:$F$52,2,0) -> BOGOTÁ, D.C. | S9762: 001 | T9762: =VLOOKUP(S9762,Códigos!$T$3:$U$14,2,0) -> BIOINDUSTRIA | U9762: 2406.71 | V9762: 28399.998
A9763: 014 | B9763: =VLOOKUP(A9763,Códigos!$H$3:$I$19,2,0) -> SUSANA ESTRADA E. | C9763: MED-37216 | D9763: 42748 | E9763: Sem 1 | F9763: 30 | G9763: 1400-0001 | H9763: =VLOOKUP(G9763,Códigos!$K$2:$L$250,2,0) -> SANTICIZER 160 | I9763: 23 | J9763: 446709.45 | K9763: 900007650 | L9763: =VLOOKUP(K9763,Códigos!$N$2:$O$376,2,0) -> PPG INDUSTRIES COLOMBIA LTDA | M9763: 003 | N9763: =VLOOKUP(M9763,Códigos!$Q$2:$R$26,2,0) -> FERRO | O9763: 05 | P9763: =VLOOKUP(O9763,Códigos!$B$2:$C$19,2,0) -> ANTIOQUIA | Q9763: 05360 | R9763: =VLOOKUP(Q9763,Códigos!$E$2:$F$52,2,0) -> ITAGÜÍ | S9763: 002 | T9763: =VLOOKUP(S9763,Códigos!$T$3:$U$14,2,0) -> ESPECIALIDADES QUIMICAS | U9763: 2406.71 | V9763: 185.61
A9764: 007 | B9764: =VLOOKUP(A9764,Códigos!$H$3:$I$19,2,0) -> NATALY VELA | C9764: MED-37223 | D9764: 42748 | E9764: Sem 1 | F9764: 60 | G9764: 900-0007 | H9764: =VLOOKUP(G9764,Códigos!$K$2:$L$250,2,0) -> SYLOID ED-30 | I9764: 150 | J9764: 4007172 | K9764: 830010908 | L9764: =VLOOKUP(K9764,Códigos!$N$2:$O$376,2,0) -> TAUROQUIMICA S.A. | M9764: 002 | N9764: =VLOOKUP(M9764,Códigos!$Q$2:$R$26,2,0) -> GENENCOR CUERO | O9764: 11 | P9764: =VLOOKUP(O9764,Códigos!$B$2:$C$19,2,0) -> BOGOTÁ, D.C. | Q9764: 11001 | R9764: =VLOOKUP(Q9764,Códigos!$E$2:$F$52,2,0) -> BOGOTÁ, D.C. | S9764: 002 | T9764: =VLOOKUP(S9764,Códigos!$T$3:$U$14,2,0) -> ESPECIALIDADES QUIMICAS | U9764: 2406.71 | V9764: 1664.9999
A9765: 022 | B9765: =VLOOKUP(A9765,Códigos!$H$3:$I$19,2,0) -> MARIA ELENA PELAEZ | C9765: MED-37221 | D9765: 42748 | E9765: Sem 1 | F9765: 30 | G9765: 1100-0060 | H9765: =VLOOKUP(G9765,Códigos!$K$2:$L$250,2,0) -> INDIFIX TEX | I9765: 10 | J9765: 55000 | K9765: 985849362 | L9765: =VLOOKUP(K9765,Códigos!$N$2:$O$376,2,0) -> TOBON MONCADA WILFREDY ALONSO 2 | M9765: 002 | N9765: =VLOOKUP(M9765,Códigos!$Q$2:$R$26,2,0) -> GENENCOR CUERO | O9765: 05 | P9765: =VLOOKUP(O9765,Códigos!$B$2:$C$19,2,0) -> ANTIOQUIA | Q9765: 05001 | R9765: =VLOOKUP(Q9765,Códigos!$E$2:$F$52,2,0) -> MEDELLÍN | S9765: 001 | T9765: =VLOOKUP(S9765,Códigos!$T$3:$U$14,2,0) -> BIOINDUSTRIA | U9765: 2406.71 | V9765: 22.852774
A9766: 014 | B9766: =VLOOKUP(A9766,Códigos!$H$3:$I$19,2,0) -> SUSANA ESTRADA E. | C9766: MED-37215 | D9766: 42748 | E9766: Sem 1 | F9766: 30 | G9766: 1400-0001 | H9766: =VLOOKUP(G9766,Códigos!$K$2:$L$250,2,0) -> SANTICIZER 160 | I9766: 20 | J9766: 270000 | K9766: 98584936 | L9766: =VLOOKUP(K9766,Códigos!$N$2:$O$376,2,0) -> TOBON MONCADA WILFREDY ALONSO | M9766: 003 | N9766: =VLOOKUP(M9766,Códigos!$Q$2:$R$26,2,0) -> FERRO | O9766: 05 | P9766: =VLOOKUP(O9766,Códigos!$B$2:$C$19,2,0) -> ANTIOQUIA | Q9766: 05001 | R9766: =VLOOKUP(Q9766,Códigos!$E$2:$F$52,2,0) -> MEDELLÍN | S9766: 002 | T9766: =VLOOKUP(S9766,Códigos!$T$3:$U$14,2,0) -> ESPECIALIDADES QUIMICAS | U9766: 2406.71 | V9766: 112.18635
A9767: 032 | B9767: =VLOOKUP(A9767,Códigos!$H$3:$I$19,2,0) -> ALEXANDRA CASTILLO | C9767: MED-37217 | D9767: 42748 | E9767: Sem 1 | F9767: 60 | G9767: 900-0012 | H9767: =VLOOKUP(G9767,Códigos!$K$2:$L$250,2,0) -> SYLOID 244 FP | I9767: 30 | J9767: 950169 | K9767: 900706331 | L9767: =VLOOKUP(K9767,Códigos!$N$2:$O$376,2,0) -> INKTECH TINTAS TECNICAS SAS | M9767: 002 | N9767: =VLOOKUP(M9767,Códigos!$Q$2:$R$26,2,0) -> GENENCOR CUERO | O9767: 11 | P9767: =VLOOKUP(O9767,Códigos!$B$2:$C$19,2,0) -> BOGOTÁ, D.C. | Q9767: 11001 | R9767: =VLOOKUP(Q9767,Códigos!$E$2:$F$52,2,0) -> BOGOTÁ, D.C. | S9767: 002 | T9767: =VLOOKUP(S9767,Códigos!$T$3:$U$14,2,0) -> ESPECIALIDADES QUIMICAS | U9767: 2406.71 | V9767: 394.79996
A9768: 032 | B9768: =VLOOKUP(A9768,Códigos!$H$3:$I$19,2,0) -> ALEXANDRA CASTILLO | C9768: MED-37227 | D9768: 42748 | E9768: Sem 1 | F9768: 60 | G9768: 1400-0001 | H9768: =VLOOKUP(G9768,Códigos!$K$2:$L$250,2,0) -> SANTICIZER 160 | I9768: 460 | J9768: 7196065.2 | K9768: 800171079 | L9768: =VLOOKUP(K9768,Códigos!$N$2:$O$376,2,0) -> PINTURAS TONNER Y CIA LTDA. | M9768: 003 | N9768: =VLOOKUP(M9768,Códigos!$Q$2:$R$26,2,0) -> FERRO | O9768: 25 | P9768: =VLOOKUP(O9768,Códigos!$B$2:$C$19,2,0) -> CUNDINAMARCA | Q9768: 25754 | R9768: =VLOOKUP(Q9768,Códigos!$E$2:$F$52,2,0) -> SOACHA | S9768: 002 | T9768: =VLOOKUP(S9768,Códigos!$T$3:$U$14,2,0) -> ESPECIALIDADES QUIMICAS | U9768: 2406.71 | V9768: 2990.001
... A9885: 022 | B9885: =VLOOKUP(A9885,Códigos!$H$3:$I$19,2,0) -> MARIA ELENA PELAEZ | C9885: MED-37339 | D9885: 42765 | E9885: Sem 1 | F9885: 30 | G9885: 1000-0001 | H9885: =VLOOKUP(G9885,Códigos!$K$2:$L$250,2,0) -> INDICANT-COLOR | I9885: 60 | J9885: 231000 | K9885: 811023874 | L9885: =VLOOKUP(K9885,Códigos!$N$2:$O$376,2,0) -> LINTEX S.A.S. | M9885: 005 | N9885: =VLOOKUP(M9885,Códigos!$Q$2:$R$26,2,0) -> ANDICOL | O9885: 05 | P9885: =VLOOKUP(O9885,Códigos!$B$2:$C$19,2,0) -> ANTIOQUIA | Q9885: 05001 | R9885: =VLOOKUP(Q9885,Códigos!$E$2:$F$52,2,0) -> MEDELLÍN | S9885: 001 | T9885: =VLOOKUP(S9885,Códigos!$T$3:$U$14,2,0) -> BIOINDUSTRIA | U9885: 2397.35 | V9885: 96.356394

Sheet Dashboard

Sheet Tablas Dinamicas
A2: VENDEDOR | B2: Suma de pre_tot | D2: VENDEDOR | E2: Suma de pre_tot_US | G2: DEPARTAMENTOS | H2: Suma de pre_tot | I2: Suma de pre_tot_US | K2: CIUDADES | L2: Suma de pre_tot | M2: Suma de pre_tot_US | T2: Suma de cantidad | U2: Suma de pre_tot
A3: LINA MERCEDES RUBIO GOMEZ | B3: 4.7741323e+09 | D3: LINA MERCEDES RUBIO GOMEZ | E3: 2518831.9 | G3: BOGOTÁ, D.C. | H3: 7.2861752e+09 | I3: 3800872.3 | K3: BOGOTÁ, D.C. | L3: 8.4784715e+09 | M3: 4418987.2 | S3: BIOINDUSTRIA | T3: 0.62920563 | U3: 0.524311
A4: SUSANA ESTRADA E. | B4: 3.6010949e+09 | D4: SUSANA ESTRADA E. | E4: 1890856.7 | G4: ANTIOQUIA | H4: 4.5633711e+09 | I4: 2402126.7 | K4: MEDELLÍN | L4: 2.0385432e+09 | M4: 1057770.8 | S4: ESPECIALIDADES QUIMICAS | T4: 0.37059322 | U4: 0.47483389
A5: JENNY GOMEZ VALENCIA | B5: 2.5739549e+09 | D5: JENNY GOMEZ VALENCIA | E5: 1363308.6 | G5: VALLE DEL CAUCA | H5: 2.7952241e+09 | I5: 1467038.1 | K5: YUMBO | L5: 1.5725332e+09 | M5: 827305.53 | S5: GENERALES | T5: 0.00020115629 | U5: 0.00085511034
A6: ALEXANDRA CASTILLO | B6: 1.6476251e+09 | D6: ALEXANDRA CASTILLO | E6: 796210.65 | G6: CUNDINAMARCA | H6: 1.7886062e+09 | I6: 925193.11 | K6: CALI | L6: 9.1580328e+08 | M6: 488269.51 | S6: Total general | T6: 1 | U6: 1
A7: MARIA ELENA PELAEZ | B7: 1.0665239e+09 | D7: MARIA ELENA PELAEZ | E7: 569084.41 | G7: ATLÁNTICO | H7: 5.0494169e+08 | I7: 267150.88 | K7: ITAGÜÍ | L7: 8.4296263e+08 | M7: 443570.43
A8: ELIANA LONDOÑO - TEXTIL | B8: 1.0439649e+09 | D8: ELIANA LONDOÑO - TEXTIL | E8: 548925.02 | G8: CALDAS | H8: 2.3737448e+08 | I8: 125426.63 | K8: ENVIGADO | L8: 6.8192215e+08 | M8: 370401.64 | S8: Etiquetas de fila | T8: Suma de pre_tot | U8: Suma de cantidad | W8: Producto | X8: Suma de cantidad
A9: NATALY VELA | B9: 9.6219494e+08 | D9: KAREN ANDREA GUALDRON | E9: 517706.92 | G9: RISARALDA | H9: 2.1830826e+08 | I9: 114090.16 | K9: LA ESTRELLA | L9: 5.1997381e+08 | M9: 274062.94 | S9: 1920 POWDERED AF | T9: 0.0011254756 | U9: 310.5 | W9: INDESIZE 103 DLC | X9: 0.066143828
A10: KAREN ANDREA GUALDRON | B10: 9.3015855e+08 | D10: NATALY VELA | E10: 500620.55 | G10: SANTANDER | H10: 2.1467554e+08 | I10: 110084.05 | K10: SOLEDAD | L10: 2.5430512e+08 | M10: 135309.02 | S10: 3055 RESIN | T10: 0.0017223997 | U10: 400 | W10: SANTICIZER 160 | X10: 0.067079246
A11: ELIANA CRISTINA LONDOÑO | B11: 4.1437972e+08 | D11: ELIANA CRISTINA LONDOÑO | E11: 213017.01 | G11: QUINDIO | H11: 43775538 | I11: 22619.946 | K11: BELLO | L11: 2.5350835e+08 | M11: 137754.77 | S11: 804 RESIN | T11: 0.012176525 | U11: 7175 | W11: TIZOR IAM | X11: 0.072073547
A12: TEXTILERAS BOGOTA | B12: 220231148 | D12: TEXTILERAS BOGOTA | E12: 116793.5 | G12: CAUCA | H12: 36371865 | I12: 17926.588 | K12: BARRANQUILLA | L12: 2.5063657e+08 | M12: 131841.85 | O12: Nombre Ciudad | P12: (Todas) | S12: 805 RESIN | T12: 0.0046867375 | U12: 2684 | W12: SYLOID ED-30 | X12: 0.074084376
A13: KAREN SEGURA | B13: 2.0439289e+08 | D13: KAREN SEGURA | E13: 92702.597 | G13: NORTE DE SANTANDER | H13: 32282456 | I13: 17166.812 | K13: MANIZALES | L13: 2.3737448e+08 | M13: 125426.63 | S13: 840 RESIN | T13: 0.0035521393 | U13: 1886.6 | W13: INDICOL SN 100 | X13: 0.086811634
A14: ANDRES BELTRAN | B14: 133874540 | D14: ANDRES BELTRAN | E14: 66881.271 | G14: TOLIMA | H14: 30684304 | I14: 15913.477 | K14: DOSQUEBRADAS | L14: 1.9653133e+08 | M14: 102691.53 | O14: CLIENTES | P14: Suma de pre_tot | S14: ADITIVO 100F | T14: 0.00066169198 | U14: 182 | W14: CATALASE 700 | X14: 0.091427063
A15: TEXTILERAS MEDELLIN | B15: 128490248 | D15: TEXTILERAS MEDELLIN | E15: 65684.932 | G15: BOYACÁ | H15: 4644920.6 | I15: 2498.5955 | K15: SOACHA | L15: 1.9379435e+08 | M15: 98750.575 | O15: AZUL K S.A. | P15: 2.2300545e+09 | S15: ADITIVO 163 | T15: 9.0660035e-05 | U15: 20 | W15: ANTIFOAM 1430 | X15: 0.1009411
A16: JUAN CAMILO PEREZ | B16: 38958551 | D16: JUAN CAMILO PEREZ | E16: 18414.877 | G16: NARIÑO | H16: 3957776.5 | I16: 1965.8253 | K16: BUCARAMANGA | L16: 1.934092e+08 | M16: 99322.637 | O16: CARTON DE COLOMBIA S.A. | P16: 6.1092107e+08 | S16: ADITIVO 3 | T16: 0.00021971436 | U16: 90 | W16: SYLOWHITE SM 405 | X16: 0.1070501
A17: JUAN GABRIEL ESCOBAR | B17: 15019185 | D17: JUAN GABRIEL ESCOBAR | E17: 8078.9142 | G17: HUILA | H17: 1628392.8 | I17: 797.81607 | K17: COTA | L17: 1.6593536e+08 | M17: 90188.918 | O17: COLORQUIMICA S.A. | P17: 4.1390351e+08 | S17: ADITIVO 500W | T17: 0.0002562227 | U17: 46 | W17: INDICANT-COLOR | X17: 0.1272543
A18: FERNEY ANDRES PATIÑO | B18: 6179997.2 | D18: FERNEY ANDRES PATIÑO | E18: 3238.5 | G18: META | H18: 535134.6 | I18: 270 | K18: SABANETA | L18: 1.5664243e+08 | M18: 82363.006 | O18: COMPAÑIA GLOBAL DE PINTURAS S.A. | P18: 6.8092566e+08 | S18: ADITIVO 51 | T18: 0.0005253142 | U18: 234.7 | W18: PURAFECT BLEND 102E | X18: 0.2071348
A19: CARLOS LAMUS | B19: 1888334.6 | D19: CARLOS LAMUS | E19: 1032.7313 | G19: BOLÍVAR | H19: 507013.8 | I19: 248.09957 | K19: PALMIRA | L19: 1.4166381e+08 | M19: 74921.614 | O19: DETERGENTES LTDA | P19: 6.3816319e+08 | S19: ADITIVO 56 | T19: 0.0044407583 | U19: 1120 | W19: Total general | X19: 1
A20: Total general | B20: 1.7763064e+10 | D20: Total general | E20: 9291389.1 | G20: Total general | H20: 1.7763064e+10 | I20: 9291389.1 | K20: CARTAGO | L20: 124800000 | M20: 55448.925 | O20: INDUSTRIAS LEMBER S.A. | P20: 6.5774878e+08 | S20: ADITIVO 56 * 200 KG | T20: 0.0079637736 | U20: 2460
K21: TOCANCIPÁ | L21: 1.1657401e+08 | M21: 56274.303 | O21: INVESA S.A. | P21: 6.8067288e+08 | S21: ADITIVO 57 | T21: 0.018321468 | U21: 5767
K22: MADRID | L22: 67989400 | M22: 35382.991 | O22: PLASTILENE S.A. | P22: 9.0908344e+08 | S22: ADITIVO 57 * 200 KG | T22: 0.019510567 | U22: 6969
A23: Etiquetas de fila | B23: Suma de cantidad | D23: Etiquetas de fila | E23: Suma de pre_tot | G23: Etiquetas de fila | H23: Suma de pre_tot_US | K23: ARMENIA | L23: 43775538 | M23: 22619.946 | O23: PRODUCTOS QUIMICOS PANAMERICANOS S.A. | P23: 1.5129656e+09 | S23: ADITIVO 57 X 21 | T23: 0.00048149795 | U23: 147
A24: 2014 | B24: 329243.1 | D24: 2014 | G24: 2014 | K24: RIONEGRO | L24: 42282817 | M24: 21340.409 | O24: TINTAS S.A.S. | P24: 3.7925597e+08 | S24: ADITIVO 61 | T24: 0.0029345573 | U24: 544
A25: Sem 1 | B25: 145568.61 | D25: Sem 1 | E25: 2.4400166e+09 | G25: Sem 1 | H25: 1360823.3 | K25: DONMATÍAS | L25: 32337500 | M25: 17310.288 | O25: Total general | P25: 8.7136946e+09 | S25: ADITIVO 65 | T25: 0.0006984865 | U25: 240
A26: Sem 2 | B26: 183674.49 | D26: Sem 2 | E26: 2.8430916e+09 | G26: Sem 2 | H26: 1576114.4 | K26: CÚCUTA | L26: 32282456 | M26: 17166.812 | S26: ADITIVO 68 | T26: 0.00012104335 | U26: 65.6
A27: 2015 | B27: 327707.33 | D27: 2015 | G27: 2015 | K27: IBAGUÉ | L27: 30534304 | M27: 15835.546 | S27: ADITIVO 71 | T27: 0.013033337 | U27: 3944
A28: Sem 1 | B28: 148689.8 | D28: Sem 1 | E28: 2.5614095e+09 | G28: Sem 1 | H28: 1401618.8 | K28: FUNZA | L28: 28343400 | M28: 14688.223 | S28: ADITIVO 87 | T28: 0.018399549 | U28: 17600
A29: Sem 2 | B29: 179017.53 | D29: Sem 2 | E29: 3.0094169e+09 | G29: Sem 2 | H29: 1573968.5 | K29: GUACHENÉ | L29: 21833875 | M29: 10724.475 | S29: ANTIFOAM 1400 | T29: 0.0024111755 | U29: 980
A30: 2016 | B30: 356544.87 | D30: 2016 | G30: 2016 | K30: PEREIRA | L30: 21776931 | M30: 11398.626 | S30: ANTIFOAM 1430 | T30: 0.031093059 | U30: 44200
A31: Sem 1 | B31: 156744.62 | D31: Sem 1 | E31: 2.7723745e+09 | G31: Sem 1 | H31: 1413735.1 | K31: TULUÁ | L31: 20843860 | M31: 11111.595 | S31: ANTIFOAM 1520 - TAMBOR | T31: 0.0042193597 | U31: 6002
A32: Sem 2 | B32: 199800.25 | D32: Sem 2 | E32: 3.5430862e+09 | G32: Sem 2 | H32: 1717369.6 | K32: JAMUNDÍ | L32: 16365650 | M32: 8339.8961 | S32: ANTIFOAM A COMPOUND | T32: 0.00020108871 | U32: 80
A33: 2017 | B33: 20526.54 | D33: 2017 | G33: 2017 | K33: MOSQUERA | L33: 15957293 | M33: 7915.9947 | S33: ANTIFOAM C EMULSION | T33: 0.011858056 | U33: 5200
A34: Sem 1 | B34: 20526.54 | D34: Sem 1 | E34: 5.9366866e+08 | G34: Sem 1 | H34: 247759.4 | K34: VILLA RICA | L34: 14537990 | M34: 7202.113 | S34: ANTIFOAM DC 1520 CUÑETE | T34: 9.5971416e-05 | U34: 80
A35: Total general | B35: 1034021.8 | D35: Total general | E35: 1.7763064e+10 | G35: Total general | H35: 9291389.1 | K35: FLORIDABLANCA | L35: 14068103 | M35: 7172.7621 | S35: ANTIFOAM-1430 NO USAR | T35: 0.0048640257 | U35: 8000
K36: GACHANCIPÁ | L36: 4975422.2 | M36: 2473.5544 | S36: ANTIPILLING 300 LUNA | T36: 0.0026733564 | U36: 5405
K37: TUNJA | L37: 4644920.6 | M37: 2498.5955 | S37: ANTIPILLING 44 LUNA | T37: 0.00026374954 | U37: 515
K38: PASTO | L38: 3957776.5 | M38: 1965.8253 | S38: ANTIPILLING 50 LUNA | T38: 0.0002718844 | U38: 251
A39: Subgrupos | B39: Suma de pre_tot | C39: Suma de pre_tot_US | E39: Etiquetas de fila | F39: Suma de cantidad | K39: CANDELARIA | L39: 3214290 | M39: 1641.0217 | S39: ANTIPILLING NEUTRA 800 | T39: 0.0017063357 | U39: 4010
A40: GENENOR DETERGENTES | B40: 0.25669289 | C40: 0.25911716 | E40: GENENCOR CUERO | F40: 371195.5 | K40: TENJO | L40: 1988281.2 | M40: 1017.6872 | S40: ANTIPILLING PRIMAFAST XLP | T40: 0.00010485241 | U40: 185
A41: GENENCOR CUERO | B41: 0.22163778 | C41: 0.22121632 | E41: GENENOR DETERGENTES | F41: 141781.4 | K41: SAN GIL | L41: 1649586.9 | M41: 764.78462 | S41: ANTIQUIEBRE 200 | T41: 0.00027101417 | U41: 1967
...

Sheet Campos en la BD
E3: Campo | F3: Descripción
E4: vendedor | F4: Código del Vendedor
E5: num_doc | F5: Número de Factura
E6: fecha | F6: Fecha de Factura
E7: dia_pla | F7: Días de Plazo (para el pago)
E8: item | F8: Código del producto
E9: cantidad | F9: Cantidad vendida
E10: pre_tot | F10: Valor de la Venta
E11: cliente | F11: Código del cliente
E12: cod_subgrupo | F12: Código del Subgrupo del Producto
E13: cod_dep | F13: Código del departamento
E14: cod_ciu | F14: Código de ciudad
... E24: nom_cco | F24: Centro de costos

Sheet Códigos
B2: cod_dep | C2: departamento | E2: cod_ciu | F2: ciudad | H2: vendedor | I2: nom_ven | K2: item | L2: des_item | N2: cliente | O2: nom_cli | Q2: cod_subgrupo | R2: nom_sub | T2: cod_cco | U2: nom_cco
B3: 05 | C3: ANTIOQUIA | E3: 05001 | F3: MEDELLÍN | H3: 001 | I3: TEXTILERAS BOGOTA | K3: 1000-0001 | L3: INDICANT-COLOR | N3: 10109050 | O3: ARDILA ALVAREZ JAIME | Q3: 001 | R3: BASF QUIMICA | T3: 001 | U3: BIOINDUSTRIA
B4: 08 | C4: ATLÁNTICO | E4: 05088 | F4: BELLO | H4: 002 | I4: KAREN ANDREA GUALDRON | K4: 1000-0004 | L4: INDISTONE | N4: 102197600 | O4: SERBEN KORSOU BUS | Q4: 002 | R4: GENENCOR CUERO | T4: 002 | U4: ESPECIALIDADES QUIMICAS
B5: 11 | C5: BOGOTÁ, D.C. | E5: 05129 | F5: CALDAS | H5: 003 | I5: LINA MERCEDES RUBIO GOMEZ | K5: 1000-0009 | L5: INDITYE | N5: 1022348758 | O5: VASCO TOVAR JHONATAN | Q5: 003 | R5: FERRO | T5: 003 | U5: GENERALES
B6: 13 | C6: BOLÍVAR | E6: 05237 | F6: DONMATÍAS | H6: 005 | I6: JENNY GOMEZ VALENCIA | K6: 1100-0002 | L6: INDINASA EG 25 | N6: 1024501802 | O6: RAMIREZ VELANDIA CINDY NATHALY | Q6: 004 | R6: AUXICOLOR LTDA | T6: 005 | U6: BIOINDUSTRIA
B7: 15 | C7: BOYACÁ | E7: 05266 | F7: ENVIGADO | H7: 007 | I7: NATALY VELA | K7: 1100-0003 | L7: VERDE FLUORESCENTE IXAS 12 | N7: 1026553774 | O7: CASTAÑEDA CARVAJAL JOHN FREDDY | Q7: 005 | R7: ANDICOL | T7: 006 | U7: BIOINDUSTRIA
B8: 17 | C8: CALDAS | E8: 05318 | F8: GUARNE | H8: 009 | I8: JUAN GABRIEL ESCOBAR | K8: 1100-0004 | L8: NARANJA FLOURESCENTE IXAS 14 | N8: 1075254363 | O8: GAITAN SANCHEZ NICOLAS | Q8: 007 | R8: QUIMICA PRODES | T8: 007 | U8: BIOINDUSTRIA
B9: 19 | C9: CAUCA | E9: 05360 | F9: ITAGÜÍ | H9: 011 | I9: FERNEY ANDRES PATIÑO | K9: 1100-0006 | L9: VIOLETA FLUORESCENTE IXAS 19 | N9: 1098657163 | O9: HERNANDEZ MELGAREJO SONIA | Q9: 008 | R9: BRENNTAG DE COLOMBIA | T9: 008 | U9: BIOINDUSTRIA
B10: 25 | C10: CUNDINAMARCA | E10: 05380 | F10: LA ESTRELLA | H10: 014 | I10: SUSANA ESTRADA E. | K10: 1100-00094 | L10: LIGANTE INDIPRINT ET | N10: 1107066316 | O10: MORENO ALEJANDRA | Q10: 009 | R10: CHEMLOGIS | T10: 009 | U10: BIOINDUSTRIA
B11: 41 | C11: HUILA | E11: 05440 | F11: MARINILLA | H11: 017 | I11: ELIANA LONDOÑO - TEXTIL | K11: 1100-00096 | L11: INDISIL K EFFECT | N11: 1114060050 | O11: GOMEZ GUANCHA JHON JANER | Q11: 010 | R11: DOW CORNING INDUSTIRAL | T11: 010 | U11: BIOINDUSTRIA
B12: 50 | C12: META | E12: 05615 | F12: RIONEGRO | H12: 018 | I12: TEXTILERAS MEDELLIN | K12: 1100-0010 | L12: ROSA FLUORESCENTE IXAS 17 | N12: 1128384563 | O12: RUIZ MURIEL ALEXANDER | Q12: 011 | R12: SURTIQUIMICOS | T12: 012 | U12: BIOINDUSTRIA
B13: 52 | C13: NARIÑO | E13: 05631 | F13: SABANETA | H13: 022 | I13: MARIA ELENA PELAEZ | K13: 1100-0023 | L13: SORBITOL 70-20 | N13: 13256744 | O13: PORTILLO URIEL | Q13: 012 | R13: AUXICOLOR | T13: 014 | U13: BIOINDUSTRIA
B14: 54 | C14: NORTE DE SANTANDER | E14: 08001 | F14: BARRANQUILLA | H14: 027 | I14: ELIANA CRISTINA LONDOÑO | K14: 1100-0035 | L14: INDICRIL BD 50 | N14: 13460191 | O14: GUERRERO CARLOS Y/O QUIMIANDES COLOMBIA | Q14: 013 | R14: DANISCO COLOMBIA LTDA | T14: 015 | U14: BIOINDUSTRIA
B15: 63 | C15: QUINDIO | E15: 08758 | F15: SOLEDAD | H15: 030 | I15: ANDRES BELTRAN | K15: 1100-0036 | L15: MERQUILUBE POLVO | N15: 13475913 | O15: GOMEZ GOMEZ LEONEL ANTONIO | Q15: 015 | R15: DUPONT NEMOURS
B16: 66 | C16: RISARALDA | E16: 11001 | F16: BOGOTÁ, D.C. | H16: 031 | I16: CARLOS LAMUS | K16: 1100-0040 | L16: GTB LIQ | N16: 1405355 | O16: GARCIA CARDONA GERMAN OCTAVIO | Q16: 021 | R16: GENENOR DETERGENTES
B17: 68 | C17: SANTANDER | E17: 13836 | F17: TURBACO | H17: 032 | I17: ALEXANDRA CASTILLO | K17: 1100-0045 | L17: INDISEC FE30 CONC | N17: 14296850 | O17: VEGA RODRIGO | Q17: 022 | R17: GENENCOR ALIMENTOS
B18: 73 | C18: TOLIMA | E18: 15001 | F18: TUNJA | H18: 035 | I18: JUAN CAMILO PEREZ | K18: 1100-0046 | L18: PRIMASOL JET R | N18: 14976902 | O18: HORMAZA JUAN JOSE Y/O INSUMOS INDUSTRIALES J.J. | Q18: 023 | R18: GENENCOR ESPECIALIDADES
B19: 76 | C19: VALLE DEL CAUCA | E19: 17001 | F19: MANIZALES | H19: 036 | I19: KAREN SEGURA | K19: 1100-0047 | L19: MERQUIFIX | N19: 14987823 | O19: URREGO FAJARDO JAIRO | Q19: 024 | R19: BIO-CAT
E20: 19300 | F20: GUACHENÉ | K20: 1100-0060 | L20: INDIFIX TEX | N20: 16751601 | O20: BELALCAZAR VALENCIA SAMUEL | Q20: 025 | R20: FERMENTIS- SAFMEX
E21: 19845 | F21: VILLA RICA | K21: 1300-0001 | L21: LUBRICANTE AF-100 * 18 KG | N21: 17133059 | O21: HIGUERA REYES GILBERTO | Q21: 027 | R21: CHEMLOGIS
E22: 25000 | K22: 1300-0017 | L22: LUBRICANTE GS-1000* 18 KG | N22: 19392110 | O22: MARTINEZ LUIS ANTONIO | Q22: 028 | R22: SOIL NET LLC
E23: 25175 | F23: CHÍA | K23: 1400-0001 | L23: SANTICIZER 160 | N23: 19423947 | O23: HERNANDEZ RIVEROS MILCIADES | Q23: 040 | R23: DUPONT
E24: 25214 | F24: COTA | K24: 1400-0002 | L24: SANTICIZER 278 | N24: 2941217 | O24: PARRA ADOLFO Y / O TINTORERIA TPQ | Q24: 100 | R24: DORF KETAL
E25: 25286 | F25: FUNZA | K25: 1400-0003 | L25: SANTICIZER 141 | N25: 29617310 | O25: MONDRAGON GARCIA SANDRA PATRICIA | Q25: 101 | R25: XIAMETER
E26: 25295 | F26: GACHANCIPÁ | K26: 1400-0004 | L26: SANTICIZER 9201 | N26: 32499129 | O26: MURILLO AGUDELO JULIA BEATRIZ | Q26: 102 | R26: MORCHEM
E27: 25386 | F27: LA MESA | K27: 1500-0001 | L27: OIL STAIN REMOVER PINT | N27: 38556806 | O27: ACOSTA NILDA MARIA
E28: 25430 | F28: MADRID | K28: 1500-0005 | L28: BRAITEX CBSX-PVO | N28: 39164426 | O28: MORALES LOPEZ MARIA MARLENY
E29: 25473 | F29: MOSQUERA | K29: 1500-0006 | L29: ANTIQUIEBRE 200 | N29: 39431004 | O29: GOMEZ GALLEGO LUZ MIRIAM
E30: 25754 | F30: SOACHA | K30: 1500-0007 | L30: CHEMILUX | N30: 39618847 | O30: NEIRA MENDEZ LUZ DARY
E31: 25799 | F31: TENJO | K31: 200-0004 | L31: DEKOL SN | N31: 39779193 | O31: MORENO CASTRO LUCED
E32: 25817 | F32: TOCANCIPÁ | K32: 200-0005 | L32: MORCHEM PL 261 | N32: 40400999 | O32: MORENO GASPAR SANDRA PATRICIA
E33: 41001 | F33: NEIVA | K33: 200-0008 | L33: KIERALON MBF | N33: 41779306 | O33: GAITAN OLAYA LEIDER ELENA
E34: 50001 | F34: VILLAVICENCIO | K34: 200-0013 | L34: MORCHEM PL 275A | N34: 42152726 | O34: MUÑOZ RINCON BEATRIZ ELENA
E35: 52001 | F35: PASTO | K35: 200-0016 | L35: INDIMOL- WS | N35: 42159702 | O35: RUIZ GUEVARA ROSA ALEJANDRA
E36: 54001 | F36: CÚCUTA | K36: 200-00188 | L36: INDIERALON MFB | N36: 4242874 | O36: RIOS DUITAMA MANUEL DE JESUS
E37: 63001 | F37: ARMENIA | K37: 200-0035 | L37: ADITIVO 500W | N37: 43181781 | O37: RENDON FRANCY LUZ
E38: 66001 | F38: PEREIRA | K38: 200-0039 | L38: HEAVY DUTY EXTERIOR SEALER 5 GALLONES | N38: 52285254 | O38: ARIZA MORENO ADRIANA
... E52: 76892 | F52: YUMBO | K52: 600-0001 | L52: ADITIVO 87 | N52: 79349853 | O52: CUCAITA TOVAR JAIRO
K53: 600-0002 | L53: ADITIVO 56 | N53: 79362280 | O53: PACHECO SALVADOR
K54: 600-0003 | L54: ADITIVO 57 | N54: 79387798 | O54: GONZALEZ GUERRERO JOSE JOAQUIN
...
